<?xml version="1.0"?>
<robot name="two_link_arm">
  <link name="base_link">
    <visual>
      <geometry><box size="0.3 0.3 0.1"/></geometry>
      <material name="gray"><color rgba="0.5 0.5 0.5 1"/></material>
    </visual>
  </link>
  <link name="link1">
    <visual>
      <geometry><cylinder length="1.0" radius="0.05"/></geometry>
      <origin xyz="0 0 0.5"/>
      <material name="blue"><color rgba="0 0 1 1"/></material>
    </visual>
  </link>
  <link name="link2">
    <visual>
      <geometry><cylinder length="0.8" radius="0.04"/></geometry>
      <origin xyz="0 0 0.4"/>
      <material name="green"><color rgba="0 1 0 1"/></material>
    </visual>
  </link>
  <joint name="joint1" type="revolute">
    <parent link="base_link"/>
    <child link="link1"/>
    <origin xyz="0 0 0.05"/>
    <axis xyz="0 0 1"/>
  </joint>
  <joint name="joint2" type="revolute">
    <parent link="link1"/>
    <child link="link2"/>
    <origin xyz="0 0 1.0"/>
    <axis xyz="0 0 1"/>
  </joint>
</robot>
